[2025-06-28T09:36:55.660+0000] {taskinstance.py:1957} INFO - Dependencies all met for dep_context=non-requeueable deps ti=<TaskInstance: user_full_etl_pipeline.run_etl manual__2025-06-28T09:36:54.341609+00:00 [queued]>
[2025-06-28T09:36:55.663+0000] {taskinstance.py:1957} INFO - Dependencies all met for dep_context=requeueable deps ti=<TaskInstance: user_full_etl_pipeline.run_etl manual__2025-06-28T09:36:54.341609+00:00 [queued]>
[2025-06-28T09:36:55.663+0000] {taskinstance.py:2171} INFO - Starting attempt 1 of 1
[2025-06-28T09:36:55.670+0000] {taskinstance.py:2192} INFO - Executing <Task(_PythonDecoratedOperator): run_etl> on 2025-06-28 09:36:54.341609+00:00
[2025-06-28T09:36:55.673+0000] {standard_task_runner.py:60} INFO - Started process 821 to run task
[2025-06-28T09:36:55.675+0000] {standard_task_runner.py:87} INFO - Running: ['***', 'tasks', 'run', 'user_full_etl_pipeline', 'run_etl', 'manual__2025-06-28T09:36:54.341609+00:00', '--job-id', '4', '--raw', '--subdir', 'DAGS_FOLDER/user_etl_dag.py', '--cfg-path', '/tmp/tmppz0vusab']
[2025-06-28T09:36:55.677+0000] {standard_task_runner.py:88} INFO - Job 4: Subtask run_etl
[2025-06-28T09:36:55.685+0000] {logging_mixin.py:188} WARNING - /home/***/.local/lib/python3.8/site-packages/***/settings.py:195 DeprecationWarning: The sql_alchemy_conn option in [core] has been moved to the sql_alchemy_conn option in [database] - the old setting has been used, but please update your config.
[2025-06-28T09:36:55.700+0000] {task_command.py:423} INFO - Running <TaskInstance: user_full_etl_pipeline.run_etl manual__2025-06-28T09:36:54.341609+00:00 [running]> on host fd578cca3b29
[2025-06-28T09:36:55.735+0000] {taskinstance.py:2481} INFO - Exporting env vars: AIRFLOW_CTX_DAG_OWNER='***' AIRFLOW_CTX_DAG_ID='user_full_etl_pipeline' AIRFLOW_CTX_TASK_ID='run_etl' AIRFLOW_CTX_EXECUTION_DATE='2025-06-28T09:36:54.341609+00:00' AIRFLOW_CTX_TRY_NUMBER='1' AIRFLOW_CTX_DAG_RUN_ID='manual__2025-06-28T09:36:54.341609+00:00'
[2025-06-28T09:36:55.736+0000] {taskinstance.py:2699} ERROR - Task failed with exception
Traceback (most recent call last):
  File "/home/airflow/.local/lib/python3.8/site-packages/airflow/models/taskinstance.py", line 433, in _execute_task
    result = execute_callable(context=context, **execute_callable_kwargs)
  File "/home/airflow/.local/lib/python3.8/site-packages/airflow/decorators/base.py", line 242, in execute
    return_value = super().execute(context)
  File "/home/airflow/.local/lib/python3.8/site-packages/airflow/operators/python.py", line 199, in execute
    return_value = self.execute_callable()
  File "/home/airflow/.local/lib/python3.8/site-packages/airflow/operators/python.py", line 216, in execute_callable
    return self.python_callable(*self.op_args, **self.op_kwargs)
  File "/opt/airflow/dags/user_etl_dag.py", line 38, in run_etl
    etl.run_full_etl_process(api_url=api_url, output_path=output_path)
TypeError: run_full_etl_process() got an unexpected keyword argument 'output_path'
[2025-06-28T09:36:55.740+0000] {taskinstance.py:1138} INFO - Marking task as FAILED. dag_id=user_full_etl_pipeline, task_id=run_etl, execution_date=20250628T093654, start_date=20250628T093655, end_date=20250628T093655
[2025-06-28T09:36:55.744+0000] {standard_task_runner.py:107} ERROR - Failed to execute job 4 for task run_etl (run_full_etl_process() got an unexpected keyword argument 'output_path'; 821)
[2025-06-28T09:36:55.772+0000] {local_task_job_runner.py:234} INFO - Task exited with return code 1
[2025-06-28T09:36:55.779+0000] {taskinstance.py:3281} INFO - 0 downstream tasks scheduled from follow-on schedule check
